# Copyright 2025 IBM Corp.
#
# Licensed under the Apache License, Version 2.0 (the "License");
# you may not use this file except in compliance with the License.
# You may obtain a copy of the License at
#
#     http://www.apache.org/licenses/LICENSE-2.0
#
# Unless required by applicable law or agreed to in writing, software
# distributed under the License is distributed on an "AS IS" BASIS,
# WITHOUT WARRANTIES OR CONDITIONS OF ANY KIND, either express or implied.
# See the License for the specific language governing permissions and
# limitations under the License.


import unittest

from beeai_framework.errors import (
    ArgumentError,
    FrameworkError,
    UnimplementedError,
)


class TestFrameworkError(unittest.TestCase):
    """
    Test cases for Framework Error

    Note that FrameworkError does not support passing cause on constructor.
    In these tests this is setup directly by assigning error.__cause__
    In consuming code we expect to use 'raise ValueError("Calculation failed") from e'
    """

    # TODO: Add test methods that create actual exceptions
    # TODO: Update direct setting of __cause__ after instantiation with use of constructor

    def test_basic_exception(self) -> None:
        err = FrameworkError("Basic")
        self.assertEqual(err.message, "Basic")
        self.assertTrue(err.is_fatal())
        self.assertFalse(err.is_retryable())
        # Will be this exception or exception at end of chain
        self.assertEqual(err.get_cause(), err)
        self.assertEqual(err.name(), "FrameworkError")

    def test_custom_properties(self) -> None:
        err = FrameworkError("Custom", is_fatal=False, is_retryable=True)
        self.assertFalse(err.is_fatal())
        self.assertTrue(err.is_retryable())

    # Get cause returns the last exception in the chain - *itself* otherwise
    def test_cause_single(self) -> None:
        err = FrameworkError("Error")
        self.assertEqual(err.get_cause(), err)

    def test_cause(self) -> None:
        # Often a standard exception will be the original cause
        inner_err = ValueError("Inner")
        err = FrameworkError("Outer")
        err.__cause__ = inner_err
        self.assertEqual(err.get_cause(), inner_err)

    def test_has_fatal_error(self) -> None:
        err = FrameworkError("Fatal", is_fatal=True)
        self.assertTrue(err.has_fatal_error())

        err2 = FrameworkError("Non-fatal", is_fatal=False)
        self.assertFalse(err2.has_fatal_error())

        inner_err = ValueError("Inner error")
        err3 = FrameworkError("Outer non-fatal", is_fatal=False)
        err3.__cause__ = inner_err
        self.assertFalse(err3.has_fatal_error())

        inner_err2 = FrameworkError("Inner fatal", is_fatal=True)
        err4 = FrameworkError("Outer non-fatal", is_fatal=False)
        err4.__cause__ = inner_err2
        self.assertTrue(err4.has_fatal_error())

    def test_traverse_errors(self) -> None:
        # Simple - one level of nesting - so 2 in total
        inner_err = ValueError("error 2")
        err = FrameworkError("error 1")
        err.__cause__ = inner_err
        errors = err.traverse_errors()
        self.assertEqual(len(errors), 2)
        self.assertIn(err, errors)
        self.assertIn(inner_err, errors)

        # Test deeper nesting - 4
        err4 = ValueError("error 4")
        err3 = TypeError("error 3")
        err3.__cause__ = err4
        err2 = FrameworkError("error 2")
        err2.__cause__ = err3
        err1 = FrameworkError("error 1")
        err1.__cause__ = err2
        errors = err1.traverse_errors()
        # count includes the outermost error (1)
        self.assertEqual(len(errors), 4)
        self.assertIn(err1, errors)
        self.assertIn(err2, errors)
        self.assertIn(err3, errors)
        self.assertIn(err4, errors)

    # @unittest.skip("TODO: Skip as message ie str(err) needs to be used in dump/explain")
    def test_explain(self) -> None:
        inner_err = ValueError("Inner")
        err = FrameworkError("Outer")
        err.__cause__ = inner_err
        explanation = err.explain()
        self.assertIn("Outer", explanation)
        self.assertIn("Caused by: Inner", explanation)

        # Test with an exception that doesn't have a 'message' attribute (not all do)
        class NoMessageError(Exception):
            pass

        inner_err2 = NoMessageError()
        err2 = FrameworkError("Outer error")
        err2.__cause__ = inner_err2
        explanation2 = err2.explain()
        self.assertIn("Outer error", explanation2)
        self.assertIn("Caused by: NoMessageError", explanation2)

    def test_dump(self) -> None:
        inner_err = ValueError("Inner ")
        err = FrameworkError("Outer", is_fatal=True, is_retryable=False)
        err.__cause__ = inner_err
        dump = err.dump()
        self.assertIn("Class: FrameworkError, Fatal: Fatal, Retryable: , Message: Outer", dump)
        self.assertIn("Caused By: Class: ValueError, Message: Inner", dump)

        # Test with an exception that doesn't have 'is_fatal' and 'is_retryable' attributes
        inner_err2 = TypeError("Type error")
        err2 = FrameworkError("Outer")
        err2.__cause__ = inner_err2
        dump2 = err2.dump()
        self.assertIn("Class: FrameworkError, Fatal: Fatal, Retryable: , Message: Outer", dump2)  # Outer
        self.assertIn("Caused By: Class: TypeError, Message: Type error", dump2)  # Inner

    # @unittest.skip("TODO: Skip as wrapped exception is not implemented correctly")
    def test_ensure(self) -> None:
        inner_err = ValueError("Value error")
        wrapped_err = FrameworkError.ensure(inner_err)
        self.assertIsInstance(wrapped_err, FrameworkError)
        self.assertEqual(wrapped_err.get_cause(), inner_err)
        self.assertEqual(str(inner_err), wrapped_err.message)

        # Ensure doesn't re-wrap a FrameworkError
        fw_err = FrameworkError("Already a FrameworkError")
        wrapped_fw_err = FrameworkError.ensure(fw_err)
        self.assertIs(wrapped_fw_err, fw_err)  # Check it returns the original.

    # Basic tests for custom errors. Not much new behaviour, only default properties
    def test_not_implemented_error(self) -> None:
        err = UnimplementedError()
        self.assertEqual(err.message, "Not implemented!")
        self.assertTrue(err.is_fatal())
        self.assertFalse(err.is_retryable())

        err2 = UnimplementedError("Custom not implemented message")
        self.assertEqual(err2.message, "Custom not implemented message")

    def test_value_framework_error(self) -> None:
        err = ArgumentError()
        self.assertEqual(err.message, "Provided value is not supported!")
        self.assertTrue(err.is_fatal())
        self.assertFalse(err.is_retryable())

        err2 = ArgumentError("Custom argument error message")
        self.assertEqual(err2.message, "Custom argument error message")


if __name__ == "__main__":
    unittest.main()
